Internal Server Error: /api/protected/
Traceback (most recent call last):
  File "/usr/local/lib/python3.11/site-packages/rest_framework/request.py", line 74, in wrap_attributeerrors
    yield
  File "/usr/local/lib/python3.11/site-packages/rest_framework/request.py", line 231, in user
    self._authenticate()
  File "/usr/local/lib/python3.11/site-packages/rest_framework/request.py", line 384, in _authenticate
    user_auth_tuple = authenticator.authenticate(self)
                      ^^^^^^^^^^^^^^^^^^^^^^^^^^^^^^^^
  File "/app/users/authentication.py", line 20, in authenticate
    user = User.objects.get(id=user_id)
           ^^^^^^^^^^^^
  File "/usr/local/lib/python3.11/site-packages/django/db/models/manager.py", line 196, in __get__
    raise AttributeError(
AttributeError: Manager isn't available; 'auth.User' has been swapped for 'users.CustomUser'

During handling of the above exception, another exception occurred:

Traceback (most recent call last):
  File "/usr/local/lib/python3.11/site-packages/django/core/handlers/exception.py", line 55, in inner
    response = get_response(request)
               ^^^^^^^^^^^^^^^^^^^^^
  File "/usr/local/lib/python3.11/site-packages/django/core/handlers/base.py", line 197, in _get_response
    response = wrapped_callback(request, *callback_args, **callback_kwargs)
               ^^^^^^^^^^^^^^^^^^^^^^^^^^^^^^^^^^^^^^^^^^^^^^^^^^^^^^^^^^^^
  File "/usr/local/lib/python3.11/site-packages/django/views/decorators/csrf.py", line 65, in _view_wrapper
    return view_func(request, *args, **kwargs)
           ^^^^^^^^^^^^^^^^^^^^^^^^^^^^^^^^^^^
  File "/usr/local/lib/python3.11/site-packages/django/views/generic/base.py", line 104, in view
    return self.dispatch(request, *args, **kwargs)
           ^^^^^^^^^^^^^^^^^^^^^^^^^^^^^^^^^^^^^^^
  File "/usr/local/lib/python3.11/site-packages/rest_framework/views.py", line 509, in dispatch
    response = self.handle_exception(exc)
               ^^^^^^^^^^^^^^^^^^^^^^^^^^
  File "/usr/local/lib/python3.11/site-packages/rest_framework/views.py", line 469, in handle_exception
    self.raise_uncaught_exception(exc)
  File "/usr/local/lib/python3.11/site-packages/rest_framework/views.py", line 480, in raise_uncaught_exception
    raise exc
  File "/usr/local/lib/python3.11/site-packages/rest_framework/views.py", line 497, in dispatch
    self.initial(request, *args, **kwargs)
  File "/usr/local/lib/python3.11/site-packages/rest_framework/views.py", line 414, in initial
    self.perform_authentication(request)
  File "/usr/local/lib/python3.11/site-packages/rest_framework/views.py", line 324, in perform_authentication
    request.user
  File "/usr/local/lib/python3.11/site-packages/rest_framework/request.py", line 230, in user
    with wrap_attributeerrors():
  File "/usr/local/lib/python3.11/contextlib.py", line 158, in __exit__
    self.gen.throw(typ, value, traceback)
  File "/usr/local/lib/python3.11/site-packages/rest_framework/request.py", line 78, in wrap_attributeerrors
    raise exc.with_traceback(info[2])
  File "/usr/local/lib/python3.11/site-packages/rest_framework/request.py", line 74, in wrap_attributeerrors
    yield
  File "/usr/local/lib/python3.11/site-packages/rest_framework/request.py", line 231, in user
    self._authenticate()
  File "/usr/local/lib/python3.11/site-packages/rest_framework/request.py", line 384, in _authenticate
    user_auth_tuple = authenticator.authenticate(self)
                      ^^^^^^^^^^^^^^^^^^^^^^^^^^^^^^^^
  File "/app/users/authentication.py", line 20, in authenticate
    user = User.objects.get(id=user_id)
           ^^^^^^^^^^^^
  File "/usr/local/lib/python3.11/site-packages/django/db/models/manager.py", line 196, in __get__
    raise AttributeError(
rest_framework.request.WrappedAttributeError: Manager isn't available; 'auth.User' has been swapped for 'users.CustomUser'
Internal Server Error: /api/protected/
Traceback (most recent call last):
  File "/usr/local/lib/python3.11/site-packages/rest_framework/request.py", line 74, in wrap_attributeerrors
    yield
  File "/usr/local/lib/python3.11/site-packages/rest_framework/request.py", line 231, in user
    self._authenticate()
  File "/usr/local/lib/python3.11/site-packages/rest_framework/request.py", line 384, in _authenticate
    user_auth_tuple = authenticator.authenticate(self)
                      ^^^^^^^^^^^^^^^^^^^^^^^^^^^^^^^^
  File "/app/users/authentication.py", line 20, in authenticate
    user = User.objects.get(id=user_id)
           ^^^^^^^^^^^^
  File "/usr/local/lib/python3.11/site-packages/django/db/models/manager.py", line 196, in __get__
    raise AttributeError(
AttributeError: Manager isn't available; 'auth.User' has been swapped for 'users.CustomUser'

During handling of the above exception, another exception occurred:

Traceback (most recent call last):
  File "/usr/local/lib/python3.11/site-packages/django/core/handlers/exception.py", line 55, in inner
    response = get_response(request)
               ^^^^^^^^^^^^^^^^^^^^^
  File "/usr/local/lib/python3.11/site-packages/django/core/handlers/base.py", line 197, in _get_response
    response = wrapped_callback(request, *callback_args, **callback_kwargs)
               ^^^^^^^^^^^^^^^^^^^^^^^^^^^^^^^^^^^^^^^^^^^^^^^^^^^^^^^^^^^^
  File "/usr/local/lib/python3.11/site-packages/django/views/decorators/csrf.py", line 65, in _view_wrapper
    return view_func(request, *args, **kwargs)
           ^^^^^^^^^^^^^^^^^^^^^^^^^^^^^^^^^^^
  File "/usr/local/lib/python3.11/site-packages/django/views/generic/base.py", line 104, in view
    return self.dispatch(request, *args, **kwargs)
           ^^^^^^^^^^^^^^^^^^^^^^^^^^^^^^^^^^^^^^^
  File "/usr/local/lib/python3.11/site-packages/rest_framework/views.py", line 509, in dispatch
    response = self.handle_exception(exc)
               ^^^^^^^^^^^^^^^^^^^^^^^^^^
  File "/usr/local/lib/python3.11/site-packages/rest_framework/views.py", line 469, in handle_exception
    self.raise_uncaught_exception(exc)
  File "/usr/local/lib/python3.11/site-packages/rest_framework/views.py", line 480, in raise_uncaught_exception
    raise exc
  File "/usr/local/lib/python3.11/site-packages/rest_framework/views.py", line 497, in dispatch
    self.initial(request, *args, **kwargs)
  File "/usr/local/lib/python3.11/site-packages/rest_framework/views.py", line 414, in initial
    self.perform_authentication(request)
  File "/usr/local/lib/python3.11/site-packages/rest_framework/views.py", line 324, in perform_authentication
    request.user
  File "/usr/local/lib/python3.11/site-packages/rest_framework/request.py", line 230, in user
    with wrap_attributeerrors():
  File "/usr/local/lib/python3.11/contextlib.py", line 158, in __exit__
    self.gen.throw(typ, value, traceback)
  File "/usr/local/lib/python3.11/site-packages/rest_framework/request.py", line 78, in wrap_attributeerrors
    raise exc.with_traceback(info[2])
  File "/usr/local/lib/python3.11/site-packages/rest_framework/request.py", line 74, in wrap_attributeerrors
    yield
  File "/usr/local/lib/python3.11/site-packages/rest_framework/request.py", line 231, in user
    self._authenticate()
  File "/usr/local/lib/python3.11/site-packages/rest_framework/request.py", line 384, in _authenticate
    user_auth_tuple = authenticator.authenticate(self)
                      ^^^^^^^^^^^^^^^^^^^^^^^^^^^^^^^^
  File "/app/users/authentication.py", line 20, in authenticate
    user = User.objects.get(id=user_id)
           ^^^^^^^^^^^^
  File "/usr/local/lib/python3.11/site-packages/django/db/models/manager.py", line 196, in __get__
    raise AttributeError(
rest_framework.request.WrappedAttributeError: Manager isn't available; 'auth.User' has been swapped for 'users.CustomUser'
Internal Server Error: /api/protected/
Traceback (most recent call last):
  File "/usr/local/lib/python3.11/site-packages/rest_framework/request.py", line 74, in wrap_attributeerrors
    yield
  File "/usr/local/lib/python3.11/site-packages/rest_framework/request.py", line 231, in user
    self._authenticate()
  File "/usr/local/lib/python3.11/site-packages/rest_framework/request.py", line 384, in _authenticate
    user_auth_tuple = authenticator.authenticate(self)
                      ^^^^^^^^^^^^^^^^^^^^^^^^^^^^^^^^
  File "/app/users/authentication.py", line 20, in authenticate
    user = User.objects.get(id=user_id)
           ^^^^^^^^^^^^
  File "/usr/local/lib/python3.11/site-packages/django/db/models/manager.py", line 196, in __get__
    raise AttributeError(
AttributeError: Manager isn't available; 'auth.User' has been swapped for 'users.CustomUser'

During handling of the above exception, another exception occurred:

Traceback (most recent call last):
  File "/usr/local/lib/python3.11/site-packages/django/core/handlers/exception.py", line 55, in inner
    response = get_response(request)
               ^^^^^^^^^^^^^^^^^^^^^
  File "/usr/local/lib/python3.11/site-packages/django/core/handlers/base.py", line 197, in _get_response
    response = wrapped_callback(request, *callback_args, **callback_kwargs)
               ^^^^^^^^^^^^^^^^^^^^^^^^^^^^^^^^^^^^^^^^^^^^^^^^^^^^^^^^^^^^
  File "/usr/local/lib/python3.11/site-packages/django/views/decorators/csrf.py", line 65, in _view_wrapper
    return view_func(request, *args, **kwargs)
           ^^^^^^^^^^^^^^^^^^^^^^^^^^^^^^^^^^^
  File "/usr/local/lib/python3.11/site-packages/django/views/generic/base.py", line 104, in view
    return self.dispatch(request, *args, **kwargs)
           ^^^^^^^^^^^^^^^^^^^^^^^^^^^^^^^^^^^^^^^
  File "/usr/local/lib/python3.11/site-packages/rest_framework/views.py", line 509, in dispatch
    response = self.handle_exception(exc)
               ^^^^^^^^^^^^^^^^^^^^^^^^^^
  File "/usr/local/lib/python3.11/site-packages/rest_framework/views.py", line 469, in handle_exception
    self.raise_uncaught_exception(exc)
  File "/usr/local/lib/python3.11/site-packages/rest_framework/views.py", line 480, in raise_uncaught_exception
    raise exc
  File "/usr/local/lib/python3.11/site-packages/rest_framework/views.py", line 497, in dispatch
    self.initial(request, *args, **kwargs)
  File "/usr/local/lib/python3.11/site-packages/rest_framework/views.py", line 414, in initial
    self.perform_authentication(request)
  File "/usr/local/lib/python3.11/site-packages/rest_framework/views.py", line 324, in perform_authentication
    request.user
  File "/usr/local/lib/python3.11/site-packages/rest_framework/request.py", line 230, in user
    with wrap_attributeerrors():
  File "/usr/local/lib/python3.11/contextlib.py", line 158, in __exit__
    self.gen.throw(typ, value, traceback)
  File "/usr/local/lib/python3.11/site-packages/rest_framework/request.py", line 78, in wrap_attributeerrors
    raise exc.with_traceback(info[2])
  File "/usr/local/lib/python3.11/site-packages/rest_framework/request.py", line 74, in wrap_attributeerrors
    yield
  File "/usr/local/lib/python3.11/site-packages/rest_framework/request.py", line 231, in user
    self._authenticate()
  File "/usr/local/lib/python3.11/site-packages/rest_framework/request.py", line 384, in _authenticate
    user_auth_tuple = authenticator.authenticate(self)
                      ^^^^^^^^^^^^^^^^^^^^^^^^^^^^^^^^
  File "/app/users/authentication.py", line 20, in authenticate
    user = User.objects.get(id=user_id)
           ^^^^^^^^^^^^
  File "/usr/local/lib/python3.11/site-packages/django/db/models/manager.py", line 196, in __get__
    raise AttributeError(
rest_framework.request.WrappedAttributeError: Manager isn't available; 'auth.User' has been swapped for 'users.CustomUser'
Internal Server Error: /api/protected/
Traceback (most recent call last):
  File "/usr/local/lib/python3.11/site-packages/rest_framework/request.py", line 74, in wrap_attributeerrors
    yield
  File "/usr/local/lib/python3.11/site-packages/rest_framework/request.py", line 231, in user
    self._authenticate()
  File "/usr/local/lib/python3.11/site-packages/rest_framework/request.py", line 384, in _authenticate
    user_auth_tuple = authenticator.authenticate(self)
                      ^^^^^^^^^^^^^^^^^^^^^^^^^^^^^^^^
  File "/app/users/authentication.py", line 20, in authenticate
    user = User.objects.get(id=user_id)
           ^^^^^^^^^^^^
  File "/usr/local/lib/python3.11/site-packages/django/db/models/manager.py", line 196, in __get__
    raise AttributeError(
AttributeError: Manager isn't available; 'auth.User' has been swapped for 'users.CustomUser'

During handling of the above exception, another exception occurred:

Traceback (most recent call last):
  File "/usr/local/lib/python3.11/site-packages/django/core/handlers/exception.py", line 55, in inner
    response = get_response(request)
               ^^^^^^^^^^^^^^^^^^^^^
  File "/usr/local/lib/python3.11/site-packages/django/core/handlers/base.py", line 197, in _get_response
    response = wrapped_callback(request, *callback_args, **callback_kwargs)
               ^^^^^^^^^^^^^^^^^^^^^^^^^^^^^^^^^^^^^^^^^^^^^^^^^^^^^^^^^^^^
  File "/usr/local/lib/python3.11/site-packages/django/views/decorators/csrf.py", line 65, in _view_wrapper
    return view_func(request, *args, **kwargs)
           ^^^^^^^^^^^^^^^^^^^^^^^^^^^^^^^^^^^
  File "/usr/local/lib/python3.11/site-packages/django/views/generic/base.py", line 104, in view
    return self.dispatch(request, *args, **kwargs)
           ^^^^^^^^^^^^^^^^^^^^^^^^^^^^^^^^^^^^^^^
  File "/usr/local/lib/python3.11/site-packages/rest_framework/views.py", line 509, in dispatch
    response = self.handle_exception(exc)
               ^^^^^^^^^^^^^^^^^^^^^^^^^^
  File "/usr/local/lib/python3.11/site-packages/rest_framework/views.py", line 469, in handle_exception
    self.raise_uncaught_exception(exc)
  File "/usr/local/lib/python3.11/site-packages/rest_framework/views.py", line 480, in raise_uncaught_exception
    raise exc
  File "/usr/local/lib/python3.11/site-packages/rest_framework/views.py", line 497, in dispatch
    self.initial(request, *args, **kwargs)
  File "/usr/local/lib/python3.11/site-packages/rest_framework/views.py", line 414, in initial
    self.perform_authentication(request)
  File "/usr/local/lib/python3.11/site-packages/rest_framework/views.py", line 324, in perform_authentication
    request.user
  File "/usr/local/lib/python3.11/site-packages/rest_framework/request.py", line 230, in user
    with wrap_attributeerrors():
  File "/usr/local/lib/python3.11/contextlib.py", line 158, in __exit__
    self.gen.throw(typ, value, traceback)
  File "/usr/local/lib/python3.11/site-packages/rest_framework/request.py", line 78, in wrap_attributeerrors
    raise exc.with_traceback(info[2])
  File "/usr/local/lib/python3.11/site-packages/rest_framework/request.py", line 74, in wrap_attributeerrors
    yield
  File "/usr/local/lib/python3.11/site-packages/rest_framework/request.py", line 231, in user
    self._authenticate()
  File "/usr/local/lib/python3.11/site-packages/rest_framework/request.py", line 384, in _authenticate
    user_auth_tuple = authenticator.authenticate(self)
                      ^^^^^^^^^^^^^^^^^^^^^^^^^^^^^^^^
  File "/app/users/authentication.py", line 20, in authenticate
    user = User.objects.get(id=user_id)
           ^^^^^^^^^^^^
  File "/usr/local/lib/python3.11/site-packages/django/db/models/manager.py", line 196, in __get__
    raise AttributeError(
rest_framework.request.WrappedAttributeError: Manager isn't available; 'auth.User' has been swapped for 'users.CustomUser'
/app/users/authentication.py changed, reloading.
Watching for file changes with StatReloader
Watching for file changes with StatReloader
Usuario autenticado: david
Usuario autenticado en la vista: david
Usuario autenticado: david
Usuario autenticado en la vista: david
Unauthorized: /api/token/
Usuario autenticado: david
Usuario autenticado en la vista: david
Usuario autenticado: david
Usuario autenticado en la vista: david
Watching for file changes with StatReloader
Watching for file changes with StatReloader
Watching for file changes with StatReloader
Watching for file changes with StatReloader
No se encontró access_token en las cookies
Internal Server Error: /api/videos/
Traceback (most recent call last):
  File "/usr/local/lib/python3.11/site-packages/django/core/handlers/exception.py", line 55, in inner
    response = get_response(request)
               ^^^^^^^^^^^^^^^^^^^^^
  File "/usr/local/lib/python3.11/site-packages/django/core/handlers/base.py", line 197, in _get_response
    response = wrapped_callback(request, *callback_args, **callback_kwargs)
               ^^^^^^^^^^^^^^^^^^^^^^^^^^^^^^^^^^^^^^^^^^^^^^^^^^^^^^^^^^^^
  File "/usr/local/lib/python3.11/site-packages/django/views/decorators/csrf.py", line 65, in _view_wrapper
    return view_func(request, *args, **kwargs)
           ^^^^^^^^^^^^^^^^^^^^^^^^^^^^^^^^^^^
  File "/usr/local/lib/python3.11/site-packages/django/views/generic/base.py", line 104, in view
    return self.dispatch(request, *args, **kwargs)
           ^^^^^^^^^^^^^^^^^^^^^^^^^^^^^^^^^^^^^^^
  File "/usr/local/lib/python3.11/site-packages/rest_framework/views.py", line 509, in dispatch
    response = self.handle_exception(exc)
               ^^^^^^^^^^^^^^^^^^^^^^^^^^
  File "/usr/local/lib/python3.11/site-packages/rest_framework/views.py", line 469, in handle_exception
    self.raise_uncaught_exception(exc)
  File "/usr/local/lib/python3.11/site-packages/rest_framework/views.py", line 480, in raise_uncaught_exception
    raise exc
  File "/usr/local/lib/python3.11/site-packages/rest_framework/views.py", line 506, in dispatch
    response = handler(request, *args, **kwargs)
               ^^^^^^^^^^^^^^^^^^^^^^^^^^^^^^^^^
  File "/usr/local/lib/python3.11/site-packages/rest_framework/generics.py", line 203, in get
    return self.list(request, *args, **kwargs)
           ^^^^^^^^^^^^^^^^^^^^^^^^^^^^^^^^^^^
  File "/usr/local/lib/python3.11/site-packages/rest_framework/mixins.py", line 46, in list
    return Response(serializer.data)
                    ^^^^^^^^^^^^^^^
  File "/usr/local/lib/python3.11/site-packages/rest_framework/serializers.py", line 795, in data
    ret = super().data
          ^^^^^^^^^^^^
  File "/usr/local/lib/python3.11/site-packages/rest_framework/serializers.py", line 249, in data
    self._data = self.to_representation(self.instance)
                 ^^^^^^^^^^^^^^^^^^^^^^^^^^^^^^^^^^^^^
  File "/usr/local/lib/python3.11/site-packages/rest_framework/serializers.py", line 713, in to_representation
    return [
           ^
  File "/usr/local/lib/python3.11/site-packages/rest_framework/serializers.py", line 714, in <listcomp>
    self.child.to_representation(item) for item in iterable
    ^^^^^^^^^^^^^^^^^^^^^^^^^^^^^^^^^^
  File "/usr/local/lib/python3.11/site-packages/rest_framework/serializers.py", line 538, in to_representation
    ret[field.field_name] = field.to_representation(attribute)
                            ^^^^^^^^^^^^^^^^^^^^^^^^^^^^^^^^^^
  File "/usr/local/lib/python3.11/site-packages/rest_framework/fields.py", line 1870, in to_representation
    return method(value)
           ^^^^^^^^^^^^^
  File "/app/users/serializers.py", line 31, in get_channel_icon
    return obj.channel.profile.icon.url if obj.channel.profile.icon else None
                                           ^^^^^^^^^^^^^^^^^^^
AttributeError: 'CustomUser' object has no attribute 'profile'
No se encontró access_token en las cookies
Internal Server Error: /api/videos/
Traceback (most recent call last):
  File "/usr/local/lib/python3.11/site-packages/django/core/handlers/exception.py", line 55, in inner
    response = get_response(request)
               ^^^^^^^^^^^^^^^^^^^^^
  File "/usr/local/lib/python3.11/site-packages/django/core/handlers/base.py", line 197, in _get_response
    response = wrapped_callback(request, *callback_args, **callback_kwargs)
               ^^^^^^^^^^^^^^^^^^^^^^^^^^^^^^^^^^^^^^^^^^^^^^^^^^^^^^^^^^^^
  File "/usr/local/lib/python3.11/site-packages/django/views/decorators/csrf.py", line 65, in _view_wrapper
    return view_func(request, *args, **kwargs)
           ^^^^^^^^^^^^^^^^^^^^^^^^^^^^^^^^^^^
  File "/usr/local/lib/python3.11/site-packages/django/views/generic/base.py", line 104, in view
    return self.dispatch(request, *args, **kwargs)
           ^^^^^^^^^^^^^^^^^^^^^^^^^^^^^^^^^^^^^^^
  File "/usr/local/lib/python3.11/site-packages/rest_framework/views.py", line 509, in dispatch
    response = self.handle_exception(exc)
               ^^^^^^^^^^^^^^^^^^^^^^^^^^
  File "/usr/local/lib/python3.11/site-packages/rest_framework/views.py", line 469, in handle_exception
    self.raise_uncaught_exception(exc)
  File "/usr/local/lib/python3.11/site-packages/rest_framework/views.py", line 480, in raise_uncaught_exception
    raise exc
  File "/usr/local/lib/python3.11/site-packages/rest_framework/views.py", line 506, in dispatch
    response = handler(request, *args, **kwargs)
               ^^^^^^^^^^^^^^^^^^^^^^^^^^^^^^^^^
  File "/usr/local/lib/python3.11/site-packages/rest_framework/generics.py", line 203, in get
    return self.list(request, *args, **kwargs)
           ^^^^^^^^^^^^^^^^^^^^^^^^^^^^^^^^^^^
  File "/usr/local/lib/python3.11/site-packages/rest_framework/mixins.py", line 46, in list
    return Response(serializer.data)
                    ^^^^^^^^^^^^^^^
  File "/usr/local/lib/python3.11/site-packages/rest_framework/serializers.py", line 795, in data
    ret = super().data
          ^^^^^^^^^^^^
  File "/usr/local/lib/python3.11/site-packages/rest_framework/serializers.py", line 249, in data
    self._data = self.to_representation(self.instance)
                 ^^^^^^^^^^^^^^^^^^^^^^^^^^^^^^^^^^^^^
  File "/usr/local/lib/python3.11/site-packages/rest_framework/serializers.py", line 713, in to_representation
    return [
           ^
  File "/usr/local/lib/python3.11/site-packages/rest_framework/serializers.py", line 714, in <listcomp>
    self.child.to_representation(item) for item in iterable
    ^^^^^^^^^^^^^^^^^^^^^^^^^^^^^^^^^^
  File "/usr/local/lib/python3.11/site-packages/rest_framework/serializers.py", line 538, in to_representation
    ret[field.field_name] = field.to_representation(attribute)
                            ^^^^^^^^^^^^^^^^^^^^^^^^^^^^^^^^^^
  File "/usr/local/lib/python3.11/site-packages/rest_framework/fields.py", line 1870, in to_representation
    return method(value)
           ^^^^^^^^^^^^^
  File "/app/users/serializers.py", line 31, in get_channel_icon
    return obj.channel.profile.icon.url if obj.channel.profile.icon else None
                                           ^^^^^^^^^^^^^^^^^^^
AttributeError: 'CustomUser' object has no attribute 'profile'
No se encontró access_token en las cookies
Internal Server Error: /api/videos/
Traceback (most recent call last):
  File "/usr/local/lib/python3.11/site-packages/django/core/handlers/exception.py", line 55, in inner
    response = get_response(request)
               ^^^^^^^^^^^^^^^^^^^^^
  File "/usr/local/lib/python3.11/site-packages/django/core/handlers/base.py", line 197, in _get_response
    response = wrapped_callback(request, *callback_args, **callback_kwargs)
               ^^^^^^^^^^^^^^^^^^^^^^^^^^^^^^^^^^^^^^^^^^^^^^^^^^^^^^^^^^^^
  File "/usr/local/lib/python3.11/site-packages/django/views/decorators/csrf.py", line 65, in _view_wrapper
    return view_func(request, *args, **kwargs)
           ^^^^^^^^^^^^^^^^^^^^^^^^^^^^^^^^^^^
  File "/usr/local/lib/python3.11/site-packages/django/views/generic/base.py", line 104, in view
    return self.dispatch(request, *args, **kwargs)
           ^^^^^^^^^^^^^^^^^^^^^^^^^^^^^^^^^^^^^^^
  File "/usr/local/lib/python3.11/site-packages/rest_framework/views.py", line 509, in dispatch
    response = self.handle_exception(exc)
               ^^^^^^^^^^^^^^^^^^^^^^^^^^
  File "/usr/local/lib/python3.11/site-packages/rest_framework/views.py", line 469, in handle_exception
    self.raise_uncaught_exception(exc)
  File "/usr/local/lib/python3.11/site-packages/rest_framework/views.py", line 480, in raise_uncaught_exception
    raise exc
  File "/usr/local/lib/python3.11/site-packages/rest_framework/views.py", line 506, in dispatch
    response = handler(request, *args, **kwargs)
               ^^^^^^^^^^^^^^^^^^^^^^^^^^^^^^^^^
  File "/usr/local/lib/python3.11/site-packages/rest_framework/generics.py", line 203, in get
    return self.list(request, *args, **kwargs)
           ^^^^^^^^^^^^^^^^^^^^^^^^^^^^^^^^^^^
  File "/usr/local/lib/python3.11/site-packages/rest_framework/mixins.py", line 46, in list
    return Response(serializer.data)
                    ^^^^^^^^^^^^^^^
  File "/usr/local/lib/python3.11/site-packages/rest_framework/serializers.py", line 795, in data
    ret = super().data
          ^^^^^^^^^^^^
  File "/usr/local/lib/python3.11/site-packages/rest_framework/serializers.py", line 249, in data
    self._data = self.to_representation(self.instance)
                 ^^^^^^^^^^^^^^^^^^^^^^^^^^^^^^^^^^^^^
  File "/usr/local/lib/python3.11/site-packages/rest_framework/serializers.py", line 713, in to_representation
    return [
           ^
  File "/usr/local/lib/python3.11/site-packages/rest_framework/serializers.py", line 714, in <listcomp>
    self.child.to_representation(item) for item in iterable
    ^^^^^^^^^^^^^^^^^^^^^^^^^^^^^^^^^^
  File "/usr/local/lib/python3.11/site-packages/rest_framework/serializers.py", line 538, in to_representation
    ret[field.field_name] = field.to_representation(attribute)
                            ^^^^^^^^^^^^^^^^^^^^^^^^^^^^^^^^^^
  File "/usr/local/lib/python3.11/site-packages/rest_framework/fields.py", line 1870, in to_representation
    return method(value)
           ^^^^^^^^^^^^^
  File "/app/users/serializers.py", line 31, in get_channel_icon
    return obj.channel.profile.icon.url if obj.channel.profile.icon else None
                                           ^^^^^^^^^^^^^^^^^^^
AttributeError: 'CustomUser' object has no attribute 'profile'
Not Found: /favicon.ico
/app/users/serializers.py changed, reloading.
Watching for file changes with StatReloader
No se encontró access_token en las cookies
Watching for file changes with StatReloader
No se encontró access_token en las cookies
Unauthorized: /api/protected/
No se encontró access_token en las cookies
Unauthorized: /api/protected/
Token refrescado exitosamente para el usuario
Token refrescado exitosamente para el usuario
No se encontró access_token en las cookies
Unauthorized: /api/protected/
No se encontró access_token en las cookies
Unauthorized: /api/protected/
Usuario autenticado: david
Usuario autenticado en la vista: david
Usuario autenticado: david
Usuario autenticado en la vista: david
Usuario autenticado: david
Usuario autenticado en la vista: david
Usuario autenticado: david
Usuario autenticado en la vista: david
Usuario autenticado: david
Usuario autenticado: david
Usuario autenticado en la vista: david
Usuario autenticado: david
Usuario autenticado en la vista: david
Usuario autenticado: david
Not Found: /media/thumbnails/miniatura-1.png
Not Found: /favicon.ico
/app/backend/settings.py changed, reloading.
Watching for file changes with StatReloader
/app/users/serializers.py changed, reloading.
Watching for file changes with StatReloader
Watching for file changes with StatReloader
No se encontró access_token en las cookies
Not Found: /api/media/thumbnails/miniatura-2_5brzP7b.png
Not Found: /api/media/thumbnails/miniatura-2.png
Not Found: /api/media/icons/usuario
Not Found: /api/media/icons/usuario.png
Not Found: /api/media/icons/usuario.jpg
Not Found: /api/media/icons/usuario.png
Not Found: /api/media/thumbnails/miniatura-2.png
Not Found: /api/media/thumbnails/miniatura-2.png
Not Found: /api/media/thumbnails/miniatura-3.png
Not Found: /api/media/thumbnails/miniatura-1_1rAvG7t.png
Not Found: /api/media/thumbnails/miniatura-1_1rAvG7t.png
Not Found: /media/thumbnails/miniatura-1_1rAvG7t.png
/app/backend/settings.py changed, reloading.
Watching for file changes with StatReloader
/app/users/urls.py changed, reloading.
Watching for file changes with StatReloader
/app/users/models.py changed, reloading.
Watching for file changes with StatReloader
/app/users/models.py changed, reloading.
Watching for file changes with StatReloader
Watching for file changes with StatReloader
Watching for file changes with StatReloader
Watching for file changes with StatReloader
Watching for file changes with StatReloader
Watching for file changes with StatReloader
Not Found: /api/media/thumbnails/miniatura-2.png
Not Found: /api/media/thumbnails/miniatura-3.png
Not Found: /api/media/thumbnails/miniatura-4.png
Not Found: /api/media/videos/video1.mp4
/app/backend/settings.py changed, reloading.
Watching for file changes with StatReloader
Not Found: /favicon.ico
No se encontró access_token en las cookies
Unauthorized: /api/protected/
No se encontró access_token en las cookies
Unauthorized: /api/protected/
Token refrescado exitosamente para el usuario
Token refrescado exitosamente para el usuario
No se encontró access_token en las cookies
Unauthorized: /api/protected/
No se encontró access_token en las cookies
Unauthorized: /api/protected/
No se encontró access_token en las cookies
Unauthorized: /api/protected/
No se encontró access_token en las cookies
No se encontró access_token en las cookies
Unauthorized: /api/protected/
Usuario autenticado: david
Usuario autenticado en la vista: david
Usuario autenticado: david
Usuario autenticado en la vista: david
Usuario autenticado: david
Usuario autenticado: david
Usuario autenticado: david
Usuario autenticado en la vista: david
Usuario autenticado: david
Usuario autenticado en la vista: david
No se encontró access_token en las cookies
Usuario autenticado: david
Usuario autenticado en la vista: david
Usuario autenticado: david
Usuario autenticado en la vista: david
Usuario autenticado: david
Usuario autenticado en la vista: david
Usuario autenticado: david
Usuario autenticado: david
Usuario autenticado: david
Usuario autenticado en la vista: david
Usuario autenticado: david
Usuario autenticado en la vista: david
Usuario autenticado: david
Usuario autenticado en la vista: david
Usuario autenticado: david
Usuario autenticado: david
Usuario autenticado: david
Usuario autenticado en la vista: david
Usuario autenticado: david
Usuario autenticado en la vista: david
Usuario autenticado: david
Usuario autenticado en la vista: david
Usuario autenticado: david
Usuario autenticado en la vista: david
Usuario autenticado: david
Usuario autenticado: david
Usuario autenticado en la vista: david
Usuario autenticado: david
Usuario autenticado: david
Usuario autenticado en la vista: david
Error de autenticación: {'detail': ErrorDetail(string='Given token not valid for any token type', code='token_not_valid'), 'code': ErrorDetail(string='token_not_valid', code='token_not_valid'), 'messages': [{'token_class': ErrorDetail(string='AccessToken', code='token_not_valid'), 'token_type': ErrorDetail(string='access', code='token_not_valid'), 'message': ErrorDetail(string='Token is expired', code='token_not_valid')}]}
Unauthorized: /api/protected/
Error de autenticación: {'detail': ErrorDetail(string='Given token not valid for any token type', code='token_not_valid'), 'code': ErrorDetail(string='token_not_valid', code='token_not_valid'), 'messages': [{'token_class': ErrorDetail(string='AccessToken', code='token_not_valid'), 'token_type': ErrorDetail(string='access', code='token_not_valid'), 'message': ErrorDetail(string='Token is expired', code='token_not_valid')}]}
Unauthorized: /api/protected/
Token refrescado exitosamente para el usuario
Token refrescado exitosamente para el usuario
Error de autenticación: {'detail': ErrorDetail(string='Given token not valid for any token type', code='token_not_valid'), 'code': ErrorDetail(string='token_not_valid', code='token_not_valid'), 'messages': [{'token_class': ErrorDetail(string='AccessToken', code='token_not_valid'), 'token_type': ErrorDetail(string='access', code='token_not_valid'), 'message': ErrorDetail(string='Token is expired', code='token_not_valid')}]}
Unauthorized: /api/protected/
Error de autenticación: {'detail': ErrorDetail(string='Given token not valid for any token type', code='token_not_valid'), 'code': ErrorDetail(string='token_not_valid', code='token_not_valid'), 'messages': [{'token_class': ErrorDetail(string='AccessToken', code='token_not_valid'), 'token_type': ErrorDetail(string='access', code='token_not_valid'), 'message': ErrorDetail(string='Token is expired', code='token_not_valid')}]}
Unauthorized: /api/protected/
Usuario autenticado: david
Usuario autenticado en la vista: david
Usuario autenticado: david
Usuario autenticado en la vista: david
Usuario autenticado: david
Usuario autenticado: david
Usuario autenticado: david
Usuario autenticado en la vista: david
Usuario autenticado: david
Usuario autenticado en la vista: david
Usuario autenticado: david
Usuario autenticado en la vista: david
Usuario autenticado: david
Usuario autenticado en la vista: david
Usuario autenticado: david
Usuario autenticado: david
Usuario autenticado en la vista: david
Usuario autenticado: david
Usuario autenticado: david
Usuario autenticado en la vista: david
Usuario autenticado: david
Usuario autenticado en la vista: david
Usuario autenticado: david
Usuario autenticado en la vista: david
Usuario autenticado: david
Usuario autenticado: david
Usuario autenticado en la vista: david
Usuario autenticado: david
Usuario autenticado: david
Usuario autenticado en la vista: david
Usuario autenticado: david
Usuario autenticado en la vista: david
Usuario autenticado: david
Usuario autenticado en la vista: david
Usuario autenticado: david
Usuario autenticado: david
Usuario autenticado en la vista: david
Usuario autenticado: david
Usuario autenticado: david
Usuario autenticado en la vista: david
Usuario autenticado: david
Usuario autenticado en la vista: david
Usuario autenticado: david
Usuario autenticado en la vista: david
Usuario autenticado: david
Usuario autenticado: david
Usuario autenticado en la vista: david
Usuario autenticado: david
Usuario autenticado: david
Usuario autenticado en la vista: david
Usuario autenticado: david
Usuario autenticado en la vista: david
Usuario autenticado: david
Usuario autenticado en la vista: david
Usuario autenticado: david
Usuario autenticado: david
Usuario autenticado en la vista: david
Usuario autenticado: david
Usuario autenticado en la vista: david
Usuario autenticado: david
Usuario autenticado: david
Usuario autenticado en la vista: david
Usuario autenticado: david
Usuario autenticado en la vista: david
Usuario autenticado: david
Usuario autenticado: david
Usuario autenticado en la vista: david
Usuario autenticado: david
Usuario autenticado: david
Usuario autenticado en la vista: david
Usuario autenticado: david
Usuario autenticado: david
Usuario autenticado en la vista: david
Usuario autenticado: david
Usuario autenticado: david
Usuario autenticado en la vista: david
Error de autenticación: {'detail': ErrorDetail(string='Given token not valid for any token type', code='token_not_valid'), 'code': ErrorDetail(string='token_not_valid', code='token_not_valid'), 'messages': [{'token_class': ErrorDetail(string='AccessToken', code='token_not_valid'), 'token_type': ErrorDetail(string='access', code='token_not_valid'), 'message': ErrorDetail(string='Token is expired', code='token_not_valid')}]}
Error de autenticación: {'detail': ErrorDetail(string='Given token not valid for any token type', code='token_not_valid'), 'code': ErrorDetail(string='token_not_valid', code='token_not_valid'), 'messages': [{'token_class': ErrorDetail(string='AccessToken', code='token_not_valid'), 'token_type': ErrorDetail(string='access', code='token_not_valid'), 'message': ErrorDetail(string='Token is expired', code='token_not_valid')}]}
Unauthorized: /api/protected/
Error de autenticación: {'detail': ErrorDetail(string='Given token not valid for any token type', code='token_not_valid'), 'code': ErrorDetail(string='token_not_valid', code='token_not_valid'), 'messages': [{'token_class': ErrorDetail(string='AccessToken', code='token_not_valid'), 'token_type': ErrorDetail(string='access', code='token_not_valid'), 'message': ErrorDetail(string='Token is expired', code='token_not_valid')}]}
Error de autenticación: {'detail': ErrorDetail(string='Given token not valid for any token type', code='token_not_valid'), 'code': ErrorDetail(string='token_not_valid', code='token_not_valid'), 'messages': [{'token_class': ErrorDetail(string='AccessToken', code='token_not_valid'), 'token_type': ErrorDetail(string='access', code='token_not_valid'), 'message': ErrorDetail(string='Token is expired', code='token_not_valid')}]}
Unauthorized: /api/protected/
Token refrescado exitosamente para el usuario
Token refrescado exitosamente para el usuario
Error de autenticación: {'detail': ErrorDetail(string='Given token not valid for any token type', code='token_not_valid'), 'code': ErrorDetail(string='token_not_valid', code='token_not_valid'), 'messages': [{'token_class': ErrorDetail(string='AccessToken', code='token_not_valid'), 'token_type': ErrorDetail(string='access', code='token_not_valid'), 'message': ErrorDetail(string='Token is expired', code='token_not_valid')}]}
Unauthorized: /api/protected/
Error de autenticación: {'detail': ErrorDetail(string='Given token not valid for any token type', code='token_not_valid'), 'code': ErrorDetail(string='token_not_valid', code='token_not_valid'), 'messages': [{'token_class': ErrorDetail(string='AccessToken', code='token_not_valid'), 'token_type': ErrorDetail(string='access', code='token_not_valid'), 'message': ErrorDetail(string='Token is expired', code='token_not_valid')}]}
Unauthorized: /api/protected/
Usuario autenticado: david
Usuario autenticado en la vista: david
Usuario autenticado: david
Usuario autenticado en la vista: david
Usuario autenticado: david
Usuario autenticado: david
Usuario autenticado en la vista: david
Usuario autenticado: david
Usuario autenticado en la vista: david
Usuario autenticado: david
Watching for file changes with StatReloader
Not Found: /favicon.ico
Usuario autenticado: david
Usuario autenticado en la vista: david
Usuario autenticado: david
Usuario autenticado en la vista: david
Usuario autenticado: david
Usuario autenticado en la vista: david
Usuario autenticado: david
Usuario autenticado: david
Usuario autenticado: david
Usuario autenticado en la vista: david
Usuario autenticado: david
Usuario autenticado en la vista: david
Usuario autenticado: david
Usuario autenticado en la vista: david
Usuario autenticado: david
Usuario autenticado en la vista: david
Usuario autenticado: david
Usuario autenticado en la vista: david
Usuario autenticado: david
Usuario autenticado en la vista: david
Usuario autenticado: david
Usuario autenticado en la vista: david
Usuario autenticado: david
Usuario autenticado: david
Usuario autenticado en la vista: david
Usuario autenticado: david
Usuario autenticado en la vista: david
Usuario autenticado: david
Usuario autenticado: david
Usuario autenticado en la vista: david
Usuario autenticado: david
Usuario autenticado en la vista: david
Usuario autenticado: david
Usuario autenticado: david
Usuario autenticado en la vista: david
Usuario autenticado: david
Usuario autenticado: david
Usuario autenticado en la vista: david
Usuario autenticado: david
Usuario autenticado: david
Usuario autenticado en la vista: david
Usuario autenticado: david
Usuario autenticado en la vista: david
Usuario autenticado: david
Usuario autenticado: david
Usuario autenticado en la vista: david
Usuario autenticado: david
Usuario autenticado: david
Usuario autenticado en la vista: david
Usuario autenticado: david
Usuario autenticado: david
Usuario autenticado en la vista: david
Usuario autenticado: david
Usuario autenticado en la vista: david
Usuario autenticado: david
Usuario autenticado en la vista: david
Usuario autenticado: david
Usuario autenticado: david
Usuario autenticado: david
Usuario autenticado en la vista: david
Usuario autenticado: david
Usuario autenticado en la vista: david
Usuario autenticado: david
Usuario autenticado: david
Usuario autenticado: david
Usuario autenticado en la vista: david
Usuario autenticado: david
Usuario autenticado: david
Usuario autenticado en la vista: david
Usuario autenticado: david
Usuario autenticado en la vista: david
Usuario autenticado: david
Usuario autenticado: david
Usuario autenticado: david
Usuario autenticado en la vista: david
Usuario autenticado: david
Usuario autenticado: david
Usuario autenticado en la vista: david
Error de autenticación: {'detail': ErrorDetail(string='Given token not valid for any token type', code='token_not_valid'), 'code': ErrorDetail(string='token_not_valid', code='token_not_valid'), 'messages': [{'token_class': ErrorDetail(string='AccessToken', code='token_not_valid'), 'token_type': ErrorDetail(string='access', code='token_not_valid'), 'message': ErrorDetail(string='Token is expired', code='token_not_valid')}]}
Unauthorized: /api/protected/
Error de autenticación: {'detail': ErrorDetail(string='Given token not valid for any token type', code='token_not_valid'), 'code': ErrorDetail(string='token_not_valid', code='token_not_valid'), 'messages': [{'token_class': ErrorDetail(string='AccessToken', code='token_not_valid'), 'token_type': ErrorDetail(string='access', code='token_not_valid'), 'message': ErrorDetail(string='Token is expired', code='token_not_valid')}]}
Unauthorized: /api/protected/
Token refrescado exitosamente para el usuario
Token refrescado exitosamente para el usuario
Error de autenticación: {'detail': ErrorDetail(string='Given token not valid for any token type', code='token_not_valid'), 'code': ErrorDetail(string='token_not_valid', code='token_not_valid'), 'messages': [{'token_class': ErrorDetail(string='AccessToken', code='token_not_valid'), 'token_type': ErrorDetail(string='access', code='token_not_valid'), 'message': ErrorDetail(string='Token is expired', code='token_not_valid')}]}
Unauthorized: /api/protected/
Error de autenticación: {'detail': ErrorDetail(string='Given token not valid for any token type', code='token_not_valid'), 'code': ErrorDetail(string='token_not_valid', code='token_not_valid'), 'messages': [{'token_class': ErrorDetail(string='AccessToken', code='token_not_valid'), 'token_type': ErrorDetail(string='access', code='token_not_valid'), 'message': ErrorDetail(string='Token is expired', code='token_not_valid')}]}
Unauthorized: /api/protected/
Error de autenticación: {'detail': ErrorDetail(string='Given token not valid for any token type', code='token_not_valid'), 'code': ErrorDetail(string='token_not_valid', code='token_not_valid'), 'messages': [{'token_class': ErrorDetail(string='AccessToken', code='token_not_valid'), 'token_type': ErrorDetail(string='access', code='token_not_valid'), 'message': ErrorDetail(string='Token is expired', code='token_not_valid')}]}
Unauthorized: /api/protected/
Error de autenticación: {'detail': ErrorDetail(string='Given token not valid for any token type', code='token_not_valid'), 'code': ErrorDetail(string='token_not_valid', code='token_not_valid'), 'messages': [{'token_class': ErrorDetail(string='AccessToken', code='token_not_valid'), 'token_type': ErrorDetail(string='access', code='token_not_valid'), 'message': ErrorDetail(string='Token is expired', code='token_not_valid')}]}
Error de autenticación: {'detail': ErrorDetail(string='Given token not valid for any token type', code='token_not_valid'), 'code': ErrorDetail(string='token_not_valid', code='token_not_valid'), 'messages': [{'token_class': ErrorDetail(string='AccessToken', code='token_not_valid'), 'token_type': ErrorDetail(string='access', code='token_not_valid'), 'message': ErrorDetail(string='Token is expired', code='token_not_valid')}]}
Error de autenticación: {'detail': ErrorDetail(string='Given token not valid for any token type', code='token_not_valid'), 'code': ErrorDetail(string='token_not_valid', code='token_not_valid'), 'messages': [{'token_class': ErrorDetail(string='AccessToken', code='token_not_valid'), 'token_type': ErrorDetail(string='access', code='token_not_valid'), 'message': ErrorDetail(string='Token is expired', code='token_not_valid')}]}
Unauthorized: /api/protected/
Token refrescado exitosamente para el usuario
Usuario autenticado: david
Usuario autenticado en la vista: david
Usuario autenticado: david
Usuario autenticado en la vista: david
Usuario autenticado: david
Usuario autenticado: david
Usuario autenticado: david
Usuario autenticado en la vista: david
Usuario autenticado: david
Usuario autenticado en la vista: david
Usuario autenticado: david
Usuario autenticado en la vista: david
Usuario autenticado: david
Usuario autenticado: david
Usuario autenticado en la vista: david
Usuario autenticado: david
Usuario autenticado: david
Usuario autenticado en la vista: david
Usuario autenticado: david
Usuario autenticado: david
Usuario autenticado: david
Usuario autenticado en la vista: david
Usuario autenticado: david
Usuario autenticado en la vista: david
Usuario autenticado: david
Usuario autenticado: david
Usuario autenticado en la vista: david
Usuario autenticado: david
Usuario autenticado: david
Usuario autenticado en la vista: david
Usuario autenticado: david
Usuario autenticado: david
Usuario autenticado en la vista: david
Usuario autenticado: david
Usuario autenticado: david
Usuario autenticado: david
Usuario autenticado en la vista: david
Usuario autenticado: david
Usuario autenticado en la vista: david
Usuario autenticado: david
Usuario autenticado: david
Usuario autenticado: david
Usuario autenticado en la vista: david
Usuario autenticado: david
Usuario autenticado: david
Usuario autenticado en la vista: david
Usuario autenticado: david
Usuario autenticado: david
Usuario autenticado en la vista: david
Usuario autenticado: david
Usuario autenticado: david
Usuario autenticado en la vista: david
Usuario autenticado: david
Usuario autenticado en la vista: david
Usuario autenticado: david
Usuario autenticado: david
Usuario autenticado: david
Usuario autenticado en la vista: david
Usuario autenticado: david
Usuario autenticado: david
Usuario autenticado en la vista: david
Usuario autenticado: david
Usuario autenticado en la vista: david
Usuario autenticado: david
